2022-11-24 20:46:05,562 INFO: Main Project 3 startup [in C:\Users\prana\OneDrive\Desktop\Dummy\app\__init__.py:87]
2022-11-24 20:46:10,484 INFO: Main Project 3 startup [in C:\Users\prana\OneDrive\Desktop\Dummy\app\__init__.py:87]
2022-11-24 21:15:09,383 INFO: Main Project 3 startup [in C:\Users\prana\OneDrive\Desktop\Dummy\app\__init__.py:87]
2022-11-24 21:15:16,436 ERROR: Exception on /FOC [GET] [in C:\Users\prana\anaconda3\lib\site-packages\flask\app.py:1741]
Traceback (most recent call last):
  File "C:\Users\prana\anaconda3\lib\site-packages\flask\app.py", line 2525, in wsgi_app
    response = self.full_dispatch_request()
  File "C:\Users\prana\anaconda3\lib\site-packages\flask\app.py", line 1822, in full_dispatch_request
    rv = self.handle_user_exception(e)
  File "C:\Users\prana\anaconda3\lib\site-packages\flask\app.py", line 1820, in full_dispatch_request
    rv = self.dispatch_request()
  File "C:\Users\prana\anaconda3\lib\site-packages\flask\app.py", line 1796, in dispatch_request
    return self.ensure_sync(self.view_functions[rule.endpoint])(**view_args)
  File "C:\Users\prana\anaconda3\lib\site-packages\flask_login\utils.py", line 290, in decorated_view
    return current_app.ensure_sync(func)(*args, **kwargs)
  File "C:\Users\prana\OneDrive\Desktop\Dummy\app\main\routes.py", line 75, in FOC
    return render_template("FOC.html", data=user_list[2])
KeyError: 2
2022-11-24 21:15:19,059 ERROR: Exception on /FOC [GET] [in C:\Users\prana\anaconda3\lib\site-packages\flask\app.py:1741]
Traceback (most recent call last):
  File "C:\Users\prana\anaconda3\lib\site-packages\flask\app.py", line 2525, in wsgi_app
    response = self.full_dispatch_request()
  File "C:\Users\prana\anaconda3\lib\site-packages\flask\app.py", line 1822, in full_dispatch_request
    rv = self.handle_user_exception(e)
  File "C:\Users\prana\anaconda3\lib\site-packages\flask\app.py", line 1820, in full_dispatch_request
    rv = self.dispatch_request()
  File "C:\Users\prana\anaconda3\lib\site-packages\flask\app.py", line 1796, in dispatch_request
    return self.ensure_sync(self.view_functions[rule.endpoint])(**view_args)
  File "C:\Users\prana\anaconda3\lib\site-packages\flask_login\utils.py", line 290, in decorated_view
    return current_app.ensure_sync(func)(*args, **kwargs)
  File "C:\Users\prana\OneDrive\Desktop\Dummy\app\main\routes.py", line 75, in FOC
    return render_template("FOC.html", data=user_list[2])
KeyError: 2
2022-11-24 21:15:44,381 INFO: Main Project 3 startup [in C:\Users\prana\OneDrive\Desktop\Dummy\app\__init__.py:87]
2022-11-24 21:15:55,062 ERROR: Exception on /FOC [GET] [in C:\Users\prana\anaconda3\lib\site-packages\flask\app.py:1741]
Traceback (most recent call last):
  File "C:\Users\prana\anaconda3\lib\site-packages\flask\app.py", line 2525, in wsgi_app
    response = self.full_dispatch_request()
  File "C:\Users\prana\anaconda3\lib\site-packages\flask\app.py", line 1822, in full_dispatch_request
    rv = self.handle_user_exception(e)
  File "C:\Users\prana\anaconda3\lib\site-packages\flask\app.py", line 1820, in full_dispatch_request
    rv = self.dispatch_request()
  File "C:\Users\prana\anaconda3\lib\site-packages\flask\app.py", line 1796, in dispatch_request
    return self.ensure_sync(self.view_functions[rule.endpoint])(**view_args)
  File "C:\Users\prana\anaconda3\lib\site-packages\flask_login\utils.py", line 290, in decorated_view
    return current_app.ensure_sync(func)(*args, **kwargs)
  File "C:\Users\prana\OneDrive\Desktop\Dummy\app\main\routes.py", line 75, in FOC
    return render_template("FOC.html", data=user_list[2])
KeyError: 2
2022-11-24 21:17:34,069 INFO: Main Project 3 startup [in C:\Users\prana\OneDrive\Desktop\Dummy\app\__init__.py:87]
2022-11-24 21:17:58,435 INFO: Main Project 3 startup [in C:\Users\prana\OneDrive\Desktop\Dummy\app\__init__.py:87]
2022-11-24 21:19:27,916 INFO: Main Project 3 startup [in C:\Users\prana\OneDrive\Desktop\Dummy\app\__init__.py:87]
2022-11-24 21:19:31,843 ERROR: Exception on /FOC [GET] [in C:\Users\prana\anaconda3\lib\site-packages\flask\app.py:1741]
Traceback (most recent call last):
  File "C:\Users\prana\anaconda3\lib\site-packages\flask\app.py", line 2525, in wsgi_app
    response = self.full_dispatch_request()
  File "C:\Users\prana\anaconda3\lib\site-packages\flask\app.py", line 1822, in full_dispatch_request
    rv = self.handle_user_exception(e)
  File "C:\Users\prana\anaconda3\lib\site-packages\flask\app.py", line 1820, in full_dispatch_request
    rv = self.dispatch_request()
  File "C:\Users\prana\anaconda3\lib\site-packages\flask\app.py", line 1796, in dispatch_request
    return self.ensure_sync(self.view_functions[rule.endpoint])(**view_args)
  File "C:\Users\prana\anaconda3\lib\site-packages\flask_login\utils.py", line 290, in decorated_view
    return current_app.ensure_sync(func)(*args, **kwargs)
  File "C:\Users\prana\OneDrive\Desktop\Dummy\app\main\routes.py", line 75, in FOC
    return render_template("FOC.html", data=list[2].commits)
KeyError: 2
2022-11-24 21:20:13,549 INFO: Main Project 3 startup [in C:\Users\prana\OneDrive\Desktop\Dummy\app\__init__.py:87]
2022-11-24 21:22:45,041 INFO: Main Project 3 startup [in C:\Users\prana\OneDrive\Desktop\Dummy\app\__init__.py:87]
2022-11-24 21:22:48,267 ERROR: Exception on /FOC [GET] [in C:\Users\prana\anaconda3\lib\site-packages\flask\app.py:1741]
Traceback (most recent call last):
  File "C:\Users\prana\anaconda3\lib\site-packages\flask\app.py", line 2525, in wsgi_app
    response = self.full_dispatch_request()
  File "C:\Users\prana\anaconda3\lib\site-packages\flask\app.py", line 1822, in full_dispatch_request
    rv = self.handle_user_exception(e)
  File "C:\Users\prana\anaconda3\lib\site-packages\flask\app.py", line 1820, in full_dispatch_request
    rv = self.dispatch_request()
  File "C:\Users\prana\anaconda3\lib\site-packages\flask\app.py", line 1796, in dispatch_request
    return self.ensure_sync(self.view_functions[rule.endpoint])(**view_args)
  File "C:\Users\prana\anaconda3\lib\site-packages\flask_login\utils.py", line 290, in decorated_view
    return current_app.ensure_sync(func)(*args, **kwargs)
  File "C:\Users\prana\OneDrive\Desktop\Dummy\app\main\routes.py", line 75, in FOC
    return render_template("FOC.html", data=list["taylorj8"].commits)
KeyError: 'taylorj8'
2022-11-24 21:23:13,240 INFO: Main Project 3 startup [in C:\Users\prana\OneDrive\Desktop\Dummy\app\__init__.py:87]
2022-11-24 21:24:03,792 INFO: Main Project 3 startup [in C:\Users\prana\OneDrive\Desktop\Dummy\app\__init__.py:87]
2022-11-24 21:25:02,796 INFO: Main Project 3 startup [in C:\Users\prana\OneDrive\Desktop\Dummy\app\__init__.py:87]
2022-11-24 22:19:37,146 INFO: Main Project 3 startup [in C:\Users\prana\OneDrive\Desktop\Dummy\app\__init__.py:87]
2022-11-24 22:29:19,332 INFO: Main Project 3 startup [in C:\Users\prana\OneDrive\Desktop\Dummy\app\__init__.py:87]
2022-11-24 22:29:46,446 INFO: Main Project 3 startup [in C:\Users\prana\OneDrive\Desktop\Dummy\app\__init__.py:87]
2022-11-24 22:32:23,934 INFO: Main Project 3 startup [in C:\Users\prana\OneDrive\Desktop\Dummy\app\__init__.py:87]
2022-11-24 22:56:01,119 INFO: Main Project 3 startup [in C:\Users\prana\OneDrive\Desktop\Dummy\app\__init__.py:87]
2022-11-24 22:56:14,603 ERROR: Exception on /FOC [GET] [in C:\Users\prana\anaconda3\lib\site-packages\flask\app.py:1741]
Traceback (most recent call last):
  File "C:\Users\prana\anaconda3\lib\site-packages\flask\app.py", line 2525, in wsgi_app
    response = self.full_dispatch_request()
  File "C:\Users\prana\anaconda3\lib\site-packages\flask\app.py", line 1822, in full_dispatch_request
    rv = self.handle_user_exception(e)
  File "C:\Users\prana\anaconda3\lib\site-packages\flask\app.py", line 1820, in full_dispatch_request
    rv = self.dispatch_request()
  File "C:\Users\prana\anaconda3\lib\site-packages\flask\app.py", line 1796, in dispatch_request
    return self.ensure_sync(self.view_functions[rule.endpoint])(**view_args)
  File "C:\Users\prana\anaconda3\lib\site-packages\flask_login\utils.py", line 290, in decorated_view
    return current_app.ensure_sync(func)(*args, **kwargs)
  File "C:\Users\prana\OneDrive\Desktop\Dummy\app\main\routes.py", line 76, in FOC
    data=list["Universal"].avg_no_changes
KeyError: 'Universal'
2022-11-24 22:57:14,643 INFO: Main Project 3 startup [in C:\Users\prana\OneDrive\Desktop\Dummy\app\__init__.py:87]
2022-11-24 22:57:30,023 ERROR: Exception on /FOC [GET] [in C:\Users\prana\anaconda3\lib\site-packages\flask\app.py:1741]
Traceback (most recent call last):
  File "C:\Users\prana\anaconda3\lib\site-packages\flask\app.py", line 2525, in wsgi_app
    response = self.full_dispatch_request()
  File "C:\Users\prana\anaconda3\lib\site-packages\flask\app.py", line 1822, in full_dispatch_request
    rv = self.handle_user_exception(e)
  File "C:\Users\prana\anaconda3\lib\site-packages\flask\app.py", line 1820, in full_dispatch_request
    rv = self.dispatch_request()
  File "C:\Users\prana\anaconda3\lib\site-packages\flask\app.py", line 1796, in dispatch_request
    return self.ensure_sync(self.view_functions[rule.endpoint])(**view_args)
  File "C:\Users\prana\anaconda3\lib\site-packages\flask_login\utils.py", line 290, in decorated_view
    return current_app.ensure_sync(func)(*args, **kwargs)
  File "C:\Users\prana\OneDrive\Desktop\Dummy\app\main\routes.py", line 76, in FOC
    data=list["Universal"].avg_freq
KeyError: 'Universal'
2022-11-24 22:59:28,763 INFO: Main Project 3 startup [in C:\Users\prana\OneDrive\Desktop\Dummy\app\__init__.py:87]
